<?xml version="1.0"?>
<robot name="example_bot1" xmlns:xacro="http://www.ros.org/wiki/xacro">
    <xacro:include filename="$(find sim1)/model/robot.gazebo"/>
    <material name="green">
        <color rgba="0 1 0 1"/>
    </material>
    <link name="base_link">
        <visual>
            <origin rpy="0 0 0" xyz="0 0 0"/>
            <geometry>
                <cylinder radius="0.2" length="0.05"/>
            </geometry>
        </visual>
        <collision>
            <origin rpy="0 0 0" xyz="0 0 0"/>
            <geometry>
                <cylinder radius="0.2" length="0.05"/>
            </geometry>
        </collision>
        <inertial>
            <origin rpy="0 0 0" xyz="0 0 0"/>
            <mass value="1"/>
            <inertia ixx="100" iyy="100" izz="100" ixy="0" iyz="0" ixz="0"/>
        </inertial>
    </link>
    <link name="part1_link">
        <visual>
            <geometry>
                <box size="0.2 0.1 1"/>
            </geometry>
            <material name="green"/>
            <origin rpy="0 -1.57 0" xyz="-0.5 0 0"/>
        </visual>
        <collision>
            <geometry>
                <box size="0.2 0.1 1"/>
            </geometry>
            <material name="green"/>
            <origin rpy="0 -1.57 0" xyz="-0.5 0 0"/>
        </collision>
        <inertial>
            <origin rpy="0 0 0" xyz="0 0 0"/>
            <mass value="1"/>
            <inertia ixx="100" iyy="100" izz="100" ixy="0" iyz="0" ixz="0"/>
        </inertial>
    </link>
    <link name="part2_link">
        <visual>
            <geometry>
                <box size="1.0 0.1 0.1"/>
            </geometry>
            <origin rpy="0 0 0" xyz="0 0 0"/>
        </visual>
        <collision>
            <geometry>
                <box size="1.0 0.1 0.1"/>
            </geometry>
            <origin rpy="0 0 0" xyz="0 0 0"/>
        </collision>
        <inertial>
            <origin rpy="0 0 0" xyz="0 0 0"/>
            <mass value="1"/>
            <inertia ixx="100" iyy="100" izz="100" ixy="0" iyz="0" ixz="0"/>
        </inertial>
    </link>
    <joint name="base_arm_joint" type="revolute">
        <parent link="base_link"/>
        <child link="part1_link"/>
        <origin rpy="0 1.57 0" xyz="0 0 0"/>
        <limit effort="1000" lower="0.0" upper="1.57" velocity="1.0"/>
        <command_interface name="position">
            <param name="min">0</param>
            <param name="max">1.57</param>
        </command_interface>
        <state_interface name="position">
            <param name="initial_value">0.0</param>
        </state_interface>
    </joint>
    <joint name="part1_part2_joint" type="prismatic">
        <parent link="part1_link"/>
        <child link="part2_link"/>
        <limit effort="1000" lower="-0.5" upper="0.5" velocity="1.0"/>
        <origin rpy="0 1.57 0" xyz="-1 0 0"/>
        <command_interface name="position">
            <param name="min">-0.5</param>
            <param name="max">0.5</param>
        </command_interface>
        <state_interface name="position">
            <param name="initial_value">0.0</param>
        </state_interface>
    </joint>
    <ros2_control name="example_bot1" type="system">
        <hardware>
            <plugin>my_hw_if/MyRobotInterface</plugin>
        </hardware>
        <joint name="base_arm_joint" type="revolute">
            <parent link="base_link"/>
            <child link="part1_link"/>
            <origin rpy="0 1.57 0" xyz="0 0 0"/>
            <limit effort="1000" lower="0.0" upper="1.57" velocity="1.0"/>
            <command_interface name="position">
                <param name="min">0</param>
                <param name="max">1.57</param>
            </command_interface>
            <state_interface name="position">
                <param name="initial_value">0.0</param>
            </state_interface>
        </joint>
        <joint name="part1_part2_joint" type="prismatic">
            <parent link="part1_link"/>
            <child link="part2_link"/>
            <limit effort="1000" lower="-0.5" upper="0.5" velocity="1.0"/>
            <origin rpy="0 1.57 0" xyz="-1 0 0"/>
            <command_interface name="position">
                <param name="min">-0.5</param>
                <param name="max">0.5</param>
            </command_interface>
            <state_interface name="position">
                <param name="initial_value">0.0</param>
            </state_interface>
        </joint>
    </ros2_control>
</robot>
